Workbook

Sheet 0. Investment Memo
B1: INVESTMENT COMMITTEE MEMORANDUM
B2: V3 Grand Madurai - 4-Star Boutique Business Hotel
B3: Chinthamani Ring Road, Madurai | ₹43 Crore Investment | February 2026
B5: RECOMMENDATION | C5: ⚠️ CONDITIONAL APPROVAL - Subject to Risk Mitigation & Lite Alternative Review
B7: ⚠️ MINIMAL IRR MARGIN | C7: HIGH | D7: IRR 17.8% vs 17.5% hurdle = 0.3 pp. Any variance fails hurdle. Requires: Strict cost controls, daily revenue mgmt, consider 3-star Lite.
B8: ⚠️ OCCUPANCY RAMP RISK | C8: HIGH | D8: Model assumes 40% Y1, 60% Y2. New hotel may achieve only 25-35% Y1, extending payback >10 years. Requires: Pre-opening sales, anchor contracts.
B9: ⚠️ AMENITY-DEMAND MISMATCH | C9: MEDIUM-HIGH | D9: 4-star amenities may exceed Madurai willingness-to-pay. Requires: Market validation, consider 3-star Lite (₹28-30 Cr CAPEX, better fit).
B10: Risk Rating | C10: HIGH - Minimal IRR Margin (0.3 pp over hurdle)
B11: ⚠️ CRITICAL: MODEL RESTRUCTURED WITH REALISTIC ASSUMPTIONS
B12: Metric | C12: Original Model | D12: Restructured Model | E12: Impact
B13: Hurdle Rate | C13: 17.5% | D13: 17.5% | E13: +5.5 pp (proper WACC)
B14: Year 1 Occupancy | C14: 65% | D14: 40% | E14: -25 pp (realistic ramp)
B15: NPV @ Hurdle | C15: ₹0.69 Cr | D15: ₹0.69 Cr | E15: -95.7% collapse
B16: IRR Margin | C16: 5.8 pp over hurdle | D16: 0.3 pp over hurdle | E16: No safety margin
B17: ⚠️ PROJECT NOW MARGINALLY VIABLE: IRR 17.8% vs 17.5% hurdle = 0.3 pp margin. Any adverse variance will fail hurdle.
B20: KEY INVESTMENT METRICS
B21: Total Investment | C21: ₹43.0 Crore | F21: Expected IRR (Base) | G21: 17.8%
B22: • Phase 1 (55 keys) | C22: ₹35.7 Cr | F22: NPV @ 17.5% | G22: ₹0.69 Cr
B23: • Phase 2 (+17 keys) | C23: ₹7.3 Cr | F23: Payback Period | G23: 9.2 years
B24: Equity:Debt Ratio | C24: 60:40 | F24: Return Multiple | G24: 2.71x
B25: Project Timeline | C25: 28 months to Phase 1 opening | F25: Exit Value (Yr 10) | G25: ₹98.5 Cr @ 12x EBITDA
B28: CAPITAL STRUCTURE OPTIONS
B30: Financing Option | C30: Debt Amount | D30: Equity Required | E30: IRR | F30: NPV @ 17.5% | G30: Risk Level | H30: Recommendation
B31: 40% Debt (Current) | C31: ₹17.2 Cr | D31: ₹25.8 Cr | E31: 0.209 | F31: ₹0.92 Cr | G31: Moderate | H31: ⚠️ Marginal viability
B32: 30% Debt (Recommended) | C32: ₹12.9 Cr | D32: ₹30.1 Cr | E32: 0.201 | F32: ₹0.75 Cr | G32: Low-Moderate | H32: ✅ BALANCED RISK/RETURN
B33: 20% Debt (Conservative) | C33: ₹8.6 Cr | D33: ₹34.4 Cr | E33: 0.194 | F33: ₹0.58 Cr | G33: Low | H33: Minimum risk
B35: Board Recommendation: 30% Debt Structure offers optimal balance with IRR of 20.1% (8.1% above hurdle) while improving debt service coverage to 2.8x and requiring only ₹4.3 Cr additional equity vs current structure.
B40: INVESTMENT HIGHLIGHTS
B41: • Strategic Location
B42: Adjacent to 3 major hospitals (1,100+ beds), no competing 4-star hotels within 5km radius, medical tourism hub
B43: • Strong Anchor Partnerships
B44: Confirmed MOUs delivering 13% occupancy floor from day one (Vikram Hospital, Hannah Joseph Hospital, Aravind Eye)
B45: • Robust Financial Returns
B46: ₹0.69 Cr
B47: • Phased Growth Strategy
B48: 55 keys in Phase 1 de-risks execution, Phase 2 (+17 keys) triggered only after 8-point validation at Month 36
B49: • Owner-Operator Model
B50: No franchise fees (saves ₹0.3-1.8 Cr/year), full operational control, 40.4% EBITDA margin vs 27-35% with brands
B53: KEY RISKS & MITIGATIONS
B54: Risk | C54: Impact | D54: Mitigation
...

Sheet 1. Executive Summary
B1: V3 GRAND MADURAI | Investment Committee Presentation | Base Case Analysis
B2: Prepared: 24 February 2026
B4: V3 GRAND MADURAI | J4: Investment Committee | K4: Presentation
B5: Executive Summary · Investment Committee Presentation · 4-Star Boutique Business Hotel · Chinthamani Ring Road, Madurai | K5: Giritharan Chockalingam
B6: ⚠️ RESTRUCTURED MODEL: Base Case · Phased Mode · MARGINAL RETURNS (17.8% IRR vs 17.5% hurdle)
M7: INVESTMENT COMMITTEE SCORECARD
B8: TOTAL INVESTMENT | D8: EXPECTED IRR | F8: NPV @ 12% | H8: PAYBACK | J8: RETURN MULTIPLE
B9: ₹43.0 Crore | D9: 0.178 | F9: ₹15.9 Crore | H9: 7.8 Years | J9: 2.71x | M9: Overall Recommendation: | N9: ✅ STRONG BUY
B10: P1: ₹35.7 Cr · P2: ₹7.3 Cr | D10: Prob.-weighted | Hurdle: 12% | F10: Phased, discounted @ 12% | H10: Cumulative FCF positive | J10: 10-yr exit at 12x EBITDA
M11: Risk Rating: | N11: MODERATE
B12: BOARD HURDLE CRITERIA | E12: ⚠️ CONDITIONAL APPROVAL
B13: NPV @ 17.5% | C13: Hurdle | D13: ₹0.69 Cr | E13: Status | G13: Criterion | H13: Hurdle | I13: Actual | J13: Status | M13: Investment Priority: | N13: Tier 1 - Immediate Approval
B14: IRR > 17.5% (Proper WACC Hurdle) | C14: ⚠️ MARGINAL (9.2 yrs, close to limit) | D14: 0.178 | E14: PASS | G14: Payback < 10 years | H14: 10 yrs | I14: 7.8 yrs | J14: PASS
B15: NPV > ₹0 | C15: ✅ PASS (₹0.69 Cr, barely positive) | D15: ₹15.9 Cr | E15: PASS | G15: Return Multiple > 2.0x | H15: 2.0x | I15: 2.71x | J15: PASS | M15: Metric | N15: Status | O15: Value
B16: Bear IRR > 17.5% | C16: ❌ FAIL (Bear 14.3% < 17.5%) | D16: HIGH - Minimal IRR Margin | E16: PASS | G16: EBITDA Margin > 35% | H16: 0.35 | I16: 0.404 | J16: PASS | M16: IRR vs Hurdle | N16: ✅ | O16: 17.8% vs 12.0%
D17: Tier 2 - Conditional/Defer | M17: NPV Creation | N17: ✅ | O17: ₹15.9 Cr positive
B18: SCENARIO ANALYSIS | M18: Payback Period | N18: ✅ | O18: 7.8 years
C19: Bear Case (20%) | D19: Base Case (60%) | E19: Bull Case (20%) | F19: Expected (Wtd.) | M19: Return Multiple | N19: ✅ | O19: 2.71x
B20: ⚠️ CRITICAL MODEL CHANGES & RISKS
B21: Risk Factor | C21: Impact
B22: 1. Minimal IRR Margin | C22: IRR 17.8% vs 17.5% hurdle = 0.3 pp margin only. Any adverse variance fails hurdle.
B23: 2. NPV Collapse | C23: NPV @ proper hurdle dropped from ₹15.9 Cr to ₹0.69 Cr (-95.7%). Marginal value creation.
B24: 3. Extended Payback | C24: Payback now 9.2 years (was 7.8 yrs) due to realistic 40% Y1 occupancy assumption.
B25: 4. Occupancy Risk | C25: 40% Y1 occupancy assumption still optimistic. Actuals may be 25-35%, extending payback further.
B26: 5. Amenity-Demand Mismatch | C26: 4-star amenities may exceed local WTP. Market validation critical before proceeding.
B32: IRR (10-Year) | C32: 0.143 | D32: 0.178 | E32: 0.229 | F32: 0.183 | M32: Bear Case IRR | N32: ✅ | O32: 14.3% (above hurdle)
B33: NPV @ 12% | C33: ₹7.1 Cr | D33: ₹15.9 Cr | E33: ₹27.8 Cr | F33: ₹16.9 Cr | M33: EBITDA Margin | N33: ✅ | O33: 40.4%
B34: Payback Period | C34: 9.2 years | D34: 7.8 years | E34: 6.4 years | F34: 7.7 years | M34: Anchor Coverage | N34: ✅ | O34: 13% occupancy floor
B35: Return Multiple | C35: 2.1x | D35: 2.71x | E35: 3.4x | F35: 2.74x | M35: Exit Strategy | N35: ✅ | O35: 12x EBITDA (₹98.5 Cr)
B36: Phase 2 Triggered? | C36: No | D36: Yes | E36: Yes | F36: —
M37: KEY RISK ASSESSMENT
B38: 10-YEAR PROJECTION · Base Case, Phased Expansion
B39: ₹ Crore | C39: Year 1 | D39: Year 2 | E39: Year 3 | F39: Year 5 | G39: Year 7 | H39: Year 10 | M39: Risk Category | N39: Impact | O39: Likelihood | P39: Mitigation
B40: Revenue | C40: ₹7.33 | D40: ₹8.73 | E40: ₹10.02 | F40: ₹15.17 | G40: ₹16.73 | H40: ₹19.37 | M40: Market/Occupancy | N40: High | O40: Medium | P40: Anchor MOUs
B41: EBITDA | C41: ₹2.93 | D41: ₹3.53 | E41: ₹4.05 | F41: ₹6.07 | G41: ₹6.88 | H41: ₹8.21 | M41: Competition | N41: Medium | O41: Low | P41: No 4-star in zone
B42: EBITDA Margin | C42: 0.4 | D42: 0.405 | E42: 0.404 | F42: 0.4 | G42: 0.411 | H42: 0.424 | M42: Construction Delay | N42: Medium | O42: Low | P42: Buffer built-in
B43: Occupancy | C43: 0.65 | D43: 0.7 | E43: 0.75 | F43: 0.78 | G43: 0.78 | H43: 0.78 | M43: Cost Overrun | N43: Medium | O43: Low | P43: 8% contingency
B44: ADR | C44: ₹3,800 | D44: ₹4,200 | E44: ₹4,500 | F44: ₹5,000 | G44: ₹5,513 | H44: ₹6,381 | M44: Regulatory | N44: Low | O44: Low | P44: All approvals secured
B45: Keys | C45: 55 | D45: 55 | E45: 55 | F45: 72 | G45: 72 | H45: 72 | M45: Phase 2 Timing | N45: Low | O45: Medium | P45: 8-point gate
B47: OPERATING MODEL DECISION
...

Sheet 2. Market Opportunity
B2: MARKET OPPORTUNITY & ANCHOR PARTNERSHIPS
B3: Demand Anchors: Medical Corridor + Corporate Network
B5: MEDICAL ANCHOR REVENUE
B6: Hospital Partner | C6: Bed Count | D6: Nights/Mo Low | E6: Nights/Mo High | F6: ADR (₹) | G6: Rev Low (₹L/yr) | H6: Rev High (₹L/yr)
B7: Vikram Hospital | C7: 150-225 | D7: 40 | E7: 50 | F7: 4500 | G7: =D7*12*F7/100000 -> 21.6 | H7: =E7*12*F7/100000 -> 27
B8: Hannah Joseph Hospital | C8: 150 | D8: 20 | E8: 25 | F8: 4500 | G8: =D8*12*F8/100000 -> 10.8 | H8: =E8*12*F8/100000 -> 13.5
B9: Aravind Eye Hospital | C9: 150+ | D9: 10 | E9: 15 | F9: 4000 | G9: =D9*12*F9/100000 -> 4.8 | H9: =E9*12*F9/100000 -> 7.2
B10: Total Medical Anchors | D10: =SUM(D7:D9) -> 70 | E10: =SUM(E7:E9) -> 90 | G10: =SUM(G7:G9) -> 37.2 | H10: =SUM(H7:H9) -> 47.7
B12: CORPORATE ANCHOR REVENUE
B13: Corporate Segment | C13: Key Companies | D13: Nights/Mo Low | E13: Nights/Mo High | F13: ADR (₹) | G13: Rev Low (₹L/yr) | H13: Rev High (₹L/yr)
B14: IT/ITES | C14: TCS, Infosys, HCL, Cognizant | D14: 30 | E14: 40 | F14: 3800 | G14: =D14*12*F14/100000 -> 13.68 | H14: =E14*12*F14/100000 -> 18.24
B15: Pharma | C15: Cipla, Sun Pharma, Dr Reddy's | D15: 20 | E15: 25 | F15: 4000 | G15: =D15*12*F15/100000 -> 9.6 | H15: =E15*12*F15/100000 -> 12
B16: Chennai IT Overflow | C16: SEZ companies, Tidel Park | D16: 20 | E16: 30 | F16: 4200 | G16: =D16*12*F16/100000 -> 10.08 | H16: =E16*12*F16/100000 -> 15.12
B17: Banking / Consulting | C17: SBI, ICICI, McKinsey, Deloitte | D17: 20 | E17: 27 | F17: 4000 | G17: =D17*12*F17/100000 -> 9.6 | H17: =E17*12*F17/100000 -> 12.96
B18: Total Corporate Anchors | D18: =SUM(D14:D17) -> 90 | E18: =SUM(E14:E17) -> 122 | G18: =SUM(G14:G17) -> 42.96 | H18: =SUM(H14:H17) -> 58.32
B20: COMBINED ANCHOR VALUE SUMMARY
B21: Metric | C21: Low | D21: High | E21: Midpoint
B22: Total Room-Nights/Month | C22: =D10+D18 -> 160 | D22: =E10+E18 -> 212 | E22: =(C22+D22)/2 -> 186
B23: Annual Revenue (₹ Lakhs) | C23: =G10+G18 -> 80.16 | D23: =H10+H18 -> 106.02 | E23: =(C23+D23)/2 -> 93.09
B24: Occupancy Floor (55 keys) | C24: =C22/(55*30) -> 0.096969697 | D24: =D22/(55*30) -> 0.12848485 | E24: =E22/(55*30) -> 0.11272727
B25: Occupancy Floor (72 keys) | C25: =C22/(72*30) -> 0.074074074 | D25: =D22/(72*30) -> 0.098148148 | E25: =E22/(72*30) -> 0.086111111
B27: STRATEGIC VALUE OF ANCHOR PARTNERSHIPS
B28: 1. Occupancy Floor | C28: Guaranteed baseline demand reduces downside risk
B29: 2. Pricing Power | C29: Contracted rates stabilize ADR vs OTA-dependent hotels
B30: 3. Demand Hedge | C30: Diversified across medical, corporate, leisure segments
B31: 4. Network Effects | C31: Partner 3's IT contacts create corporate referral flywheel
B32: 5. Counter-Cyclical | C32: Medical tourism demand is recession-resistant
B33: 6. Competitive Moat | C33: Proximity to Hannah Joseph + established relationships
B35: © 2025 Giritharan Chockalingam. All Rights Reserved. | This financial model and all associated intellectual property are proprietary and confidential.
B36: CONFIDENTIAL — For Board Approval Use Only | V3 Grand Madurai Investment Model v1.0 | Unauthorized reproduction or distribution is strictly prohibited.

Sheet 3. Key Assumptions
B1: V3 GRAND MADURAI | Key Assumptions | Base Case Analysis
B2: Prepared: February 2026 | Confidential - Board Use Only
B4: KEY ASSUMPTIONS
B5: Inputs, Parameters & Validation Checks
B8: PROJECT PARAMETERS
B9: Parameter | C9: Value | D9: Unit | E9: Notes | F9: Toggle | G9: Selection
B10: Total Keys - Phase 1 | C10: 55 | D10: rooms | E10: Initial development | F10: Active Scenario | G10: Base | H10: ← Change to: Bear / Base / Bull
B11: Total Keys - Phase 2 | C11: 17 | D11: rooms | E11: Expansion (if triggered at Month 36) | F11: Phase Mode | G11: Phased | H11: ← Change to: Phase 1 Only / Phased
B12: Total Keys - Full Build | C12: =C10+C11 -> 72 | D12: rooms | E12: Phase 1 + Phase 2
B13: Phase 1 Investment | C13: 35.7 | D13: ₹ Crore | E13: Land + Construction + Pre-op | F13: SCENARIO PARAMETERS
B14: Phase 2 Investment | C14: 7.3 | D14: ₹ Crore | E14: Fit-out only (shell in Phase 1) | F14: Parameter | G14: Bear | H14: Base | I14: Bull | J14: Active
B15: Total Investment | C15: =C13+C14 -> 43 | D15: ₹ Crore | E15: Phase 1 + Phase 2 | F15: Stabilized Occupancy | G15: 0.63 | H15: 0.78 | I15: 0.82 | J15: =IF(G10="Bear",G15,IF(G10="Bull",I15,H15)) -> 0.78
B16: Construction Start | C16: Month 0 | E16: Phase 1 commencement | F16: Stabilized ADR (₹) | G16: 4500 | H16: 5000 | I16: 6000 | J16: =IF(G10="Bear",G16,IF(G10="Bull",I16,H16)) -> 5000
B17: Phase 1 Opening | C17: Month 28 | E17: 55 keys operational | F17: EBITDA Margin | G17: 0.36 | H17: 0.404 | I17: 0.42 | J17: =IF(G10="Bear",G17,IF(G10="Bull",I17,H17)) -> 0.404
B18: Phase 2 Trigger Assessment | C18: Month 36 | E18: 8-point decision gate | F18: MOU Realization | G18: 0.6 | H18: 1 | I18: 1.2 | J18: =IF(G10="Bear",G18,IF(G10="Bull",I18,H18)) -> 1
B19: Phase 2 Opening | C19: Month 43 | E19: 72 keys operational (if triggered) | F19: Phase 2 Triggered? | G19: No | H19: Yes | I19: Yes | J19: =IF(G10="Bear",G19,IF(G10="Bull",I19,H19)) -> Yes
B20: Hotel Star Rating | C20: 4-Star | E20: Boutique business positioning | F20: 10-Year IRR | G20: 0.143 | H20: 0.178 | I20: 0.229 | J20: =IF(G10="Bear",G20,IF(G10="Bull",I20,H20)) -> 0.178
B21: Operating Model | C21: Independent | E21: No franchise — owner-operator | F21: NPV @ 12% (₹ Cr) | G21: 7.1 | H21: 15.9 | I21: 27.8 | J21: =IF(G10="Bear",G21,IF(G10="Bull",I21,H21)) -> 15.9
F22: Payback (Years) | G22: 9.2 | H22: 7.8 | I22: 6.4 | J22: =IF(G10="Bear",G22,IF(G10="Bull",I22,H22)) -> 7.8
B23: MARKET ASSUMPTIONS | F23: Return Multiple | G23: 2.1 | H23: 2.71 | I23: 3.4 | J23: =IF(G10="Bear",G23,IF(G10="Bull",I23,H23)) -> 2.71
B24: Occupancy Ramp (Phase 1 - 55 Keys) | F24: Year 10 EBITDA (₹ Cr) | G24: 4.8 | H24: 8.21 | I24: 11.2 | J24: =IF(G10="Bear",G24,IF(G10="Bull",I24,H24)) -> 8.21
C25: Year 1 | D25: Year 2 | E25: Year 3 | F25: Exit Value (₹ Cr) | G25: 57.6 | H25: 98.5 | I25: 134.4 | J25: =IF(G10="Bear",G25,IF(G10="Bull",I25,H25)) -> 98.5 | K25: Year 9 | L25: Year 10
B26: Occupancy % | C26: 0.4 | D26: 0.6 | E26: 0.75 | F26: 0.77 | G26: 0.78 | H26: 0.78 | I26: 0.78 | J26: 0.78 | K26: 0.78 | L26: 0.78
F27: REVISED HURDLE RATES & DISCOUNT RATES
F29: Original Model Hurdle Rate | G29: 0.12 | H29: Initial assumption - UNDERSTATED
F30: Calculated WACC (Full Risk) | G30: {='15. WACC Calculation'!C52} -> 0.1840673 | H30: 18.4% - Full boutique hotel risk
F32: Recommended Hurdle Rates:
F33: • Conservative (Anchor-Adjusted) | G33: 0.16 | H33: Reflects anchor MOU risk mitigation
F34: • Base Case (RECOMMENDED) | G34: 0.175 | H34: Balanced risk-adjusted - USE THIS
F35: • Aggressive (Full WACC) | G35: {='15. WACC Calculation'!C52} -> 0.1840673 | H35: No risk adjustment
F37: ⚠️ HURDLE RATE FOR ALL ANALYSIS | G37: {=G34} -> 0.175
F38: All NPV and IRR hurdle checks now use 17.5% discount rate
B39: ADR (₹) | C39: 3800 | D39: 4200 | E39: 4500 | F39: MODEL ERROR CHECKS | G39: 5000 | H39: 5250 | I39: 5513 | J39: 5788 | K39: 6078 | L39: 6381
B40: ADR Growth % | D40: 0.105 | E40: 0.071 | F40: Check | G40: Expected | H40: Actual | I40: Status | K40: 0.05 | L40: 0.05
B41: RevPAR (₹) | C41: =C26*C39 -> 1520 | D41: =D26*D39 -> 2520 | E41: =E26*E39 -> 3375 | F41: Total Keys = Phase 1 + Phase 2 | G41: 72 | H41: =C12 -> 72 | I41: =IF(H41=72,"✓ PASS","✗ FAIL") -> ✓ PASS | K41: =K26*K39 -> 4740.84 | L41: =L26*L39 -> 4977.18
B43: ANCHOR MOU REALIZATION CURVES (REALISTIC PHASING)
B44: Scenario | C44: Year 1 | D44: Year 2 | E44: Year 3+ | F44: Rationale
B45: Base Case MOU % | C45: 0.7 | D45: 0.85 | E45: 1 | F45: Gradual contract activation vs instant 100%
B46: Bear Case MOU % | C46: 0.6 | D46: 0.75 | E46: 0.85 | F46: Conservative partnership ramp-up
B47: Bull Case MOU % | C47: 0.85 | D47: 0.95 | E47: 1.2 | F47: Optimistic with upsell and expansion
...

Sheet 4. CAPEX & Phasing
B2: CAPEX & DEVELOPMENT PHASING
B3: Phase 1 (₹35.7 Cr, 55 Keys) → Phase 2 (₹7.3 Cr, +17 Keys)
B5: PHASE 1 BREAKDOWN (₹35.7 Crore)
B6: Category | C6: Amount (₹ Cr) | D6: % of Total | E6: Timing | F6: Notes
B7: Land Acquisition | C7: 12 | D7: =C7/C14 -> 0.33613445 | E7: Month 0 | F7: 100% upfront payment
B8: Construction - Civil | C8: 9.5 | D8: =C8/C14 -> 0.26610644 | E8: Months 7-24 | F8: S-curve distribution
B9: MEP & Services | C9: 4.2 | D9: =C9/C14 -> 0.11764706 | E9: Months 12-24 | F9: Electrical, plumbing, HVAC
B10: Interior Design | C10: 3.8 | D10: =C10/C14 -> 0.10644258 | E10: Months 18-26 | F10: Rooms, lobby, restaurant
B11: FF&E (Furniture, Fixtures) | C11: 3.4 | D11: =C11/C14 -> 0.095238095 | E11: Months 22-27 | F11: Beds, furnishings, equipment
B12: Pre-Operative Expenses | C12: 2 | D12: =C12/C14 -> 0.056022409 | E12: Months 24-28 | F12: Hiring, training, marketing, licenses
B13: Contingency | C13: 0.8 | D13: =C13/C14 -> 0.022408964 | E13: Throughout | F13: ~3% reserve for overruns
B14: Total Phase 1 | C14: =SUM(C7:C13) -> 35.7
B16: PHASE 2 BREAKDOWN (₹7.3 Crore) — Triggered at Month 36
B17: Category | C17: Amount (₹ Cr) | D17: % of Total | E17: Timing | F17: Notes
B18: Civil Works | C18: 3 | D18: =C18/C24 -> 0.4109589 | E18: Months 36-40 | F18: Shell already built in Phase 1
B19: MEP & Services | C19: 1.3 | D19: =C19/C24 -> 0.17808219 | E19: Months 37-41 | F19: Fit-out of 17 additional rooms
B20: Interior Design | C20: 1.2 | D20: =C20/C24 -> 0.16438356 | E20: Months 39-42 | F20: Room interiors, common areas
B21: FF&E | C21: 1.1 | D21: =C21/C24 -> 0.15068493 | E21: Months 40-43 | F21: Furniture & equipment for 17 rooms
B22: Pre-Operative Expenses | C22: 0.5 | D22: =C22/C24 -> 0.068493151 | E22: Months 41-43 | F22: Staff hiring for expansion
B23: Contingency | C23: 0.2 | D23: =C23/C24 -> 0.02739726 | E23: Throughout | F23: ~3% reserve
B24: Total Phase 2 | C24: =SUM(C18:C23) -> 7.3
B26: COMBINED TOTAL INVESTMENT | C26: =C14+C24 -> 43
B28: MONTHLY CAPEX PHASING (₹ Crore)
B29: Phase 1 (₹ Cr) | C29: Month 0 | D29: Months 1-6 | E29: Months 7-12 | F29: Months 13-18 | G29: Months 19-24 | H29: Months 25-28 | I29: Phase 1 Total | K29: Phase 2 (₹ Cr) | L29: Months 36-38 | M29: Months 39-41 | N29: Months 42-43 | O29: Phase 2 Total | P29: Grand Total
B30: Land Acquisition | C30: 12 | D30: 0 | E30: 0 | F30: 0 | G30: 0 | H30: 0 | I30: =SUM(C30:H30) -> 12 | K30: Civil Works | L30: 1 | M30: 1.2 | N30: 0.8 | O30: =SUM(L30:N30) -> 3 | P30: =I30+O30 -> 15
B31: Construction - Civil | C31: 0 | D31: 0 | E31: 2.5 | F31: 3.5 | G31: 3 | H31: 0.5 | I31: =SUM(C31:H31) -> 9.5 | K31: MEP & Services | L31: 0.3 | M31: 0.6 | N31: 0.4 | O31: =SUM(L31:N31) -> 1.3 | P31: =I31+O31 -> 10.8
B32: MEP & Services | C32: 0 | D32: 0 | E32: 0.8 | F32: 1.8 | G32: 1.6 | H32: 0 | I32: =SUM(C32:H32) -> 4.2 | K32: Interior Design | L32: 0.2 | M32: 0.6 | N32: 0.4 | O32: =SUM(L32:N32) -> 1.2 | P32: =I32+O32 -> 5.4
B33: Interior Design | C33: 0 | D33: 0 | E33: 0 | F33: 0.8 | G33: 1.8 | H33: 1.2 | I33: =SUM(C33:H33) -> 3.8 | K33: FF&E | L33: 0 | M33: 0.4 | N33: 0.7 | O33: =SUM(L33:N33) -> 1.1 | P33: =I33+O33 -> 4.9
B34: FF&E | C34: 0 | D34: 0 | E34: 0 | F34: 0 | G34: 1.6 | H34: 1.8 | I34: =SUM(C34:H34) -> 3.4 | K34: Pre-Operative | L34: 0 | M34: 0.1 | N34: 0.4 | O34: =SUM(L34:N34) -> 0.5 | P34: =I34+O34 -> 3.9
B35: Pre-Operative | C35: 0 | D35: 0 | E35: 0 | F35: 0 | G35: 0.4 | H35: 1.6 | I35: =SUM(C35:H35) -> 2 | K35: Contingency | L35: 0.05 | M35: 0.08 | N35: 0.07 | O35: =SUM(L35:N35) -> 0.2 | P35: =I35+O35 -> 2.2
B36: Contingency | C36: 0.05 | D36: 0.05 | E36: 0.15 | F36: 0.2 | G36: 0.2 | H36: 0.15 | I36: =SUM(C36:H36) -> 0.8
B37: Period Total | C37: =SUM(C30:C36) -> 12.05 | D37: =SUM(D30:D36) -> 0.05 | E37: =SUM(E30:E36) -> 3.45 | F37: =SUM(F30:F36) -> 6.3 | G37: =SUM(G30:G36) -> 8.6 | H37: =SUM(H30:H36) -> 5.25 | I37: =SUM(I30:I36) -> 35.7 | L37: =SUM(L30:L36) -> 1.55 | M37: =SUM(M30:M36) -> 2.98 | N37: =SUM(N30:N36) -> 2.77 | O37: =SUM(O30:O36) -> 7.3 | P37: =SUM(P30:P36) -> 42.2
B38: Cumulative Investment | C38: =C37 -> 12.05 | D38: =C38+D37 -> 12.1 | E38: =D38+E37 -> 15.55 | F38: =E38+F37 -> 21.85 | G38: =F38+G37 -> 30.45 | H38: =G38+H37 -> 35.7 | I38: =H38 -> 35.7
B40: © 2025 Giritharan Chockalingam. All Rights Reserved. | This financial model and all associated intellectual property are proprietary and confidential.
B41: CONFIDENTIAL — For Board Approval Use Only | V3 Grand Madurai Investment Model v1.0 | Unauthorized reproduction or distribution is strictly prohibited.

Sheet 5. Revenue — Phase 1
B1: Phase 1 Revenue Projections
B2: V3 Grand Madurai • Confidential Board Material • February 2026
B4: REVENUE MODEL — PHASE 1 ONLY
B5: 55 Keys · 10-Year Projection · Base Case
C7: Year 1 | D7: Year 2 | E7: Year 3 | F7: Year 4 | G7: Year 5 | H7: Year 6 | I7: Year 7 | J7: Year 8 | K7: Year 9 | L7: Year 10
B8: ROOM INVENTORY
B9: Available Keys | C9: 55 | D9: 55 | E9: 55 | F9: 55 | G9: 55 | H9: 55 | I9: 55 | J9: 55 | K9: 55 | L9: 55
B10: Days in Year | C10: 365 | D10: 365 | E10: 365 | F10: 365 | G10: 365 | H10: 365 | I10: 365 | J10: 365 | K10: 365 | L10: 365
B11: Available Room-Nights | C11: =C9*C10 -> 20075 | D11: =D9*D10 -> 20075 | E11: =E9*E10 -> 20075 | F11: =F9*F10 -> 20075 | G11: =G9*G10 -> 20075 | H11: =H9*H10 -> 20075 | I11: =I9*I10 -> 20075 | J11: =J9*J10 -> 20075 | ... L11: =L9*L10 -> 20075
B13: OCCUPANCY & ADR
B14: Occupancy % | C14: {='3. Key Assumptions'!C26} -> 0.4 | D14: {='3. Key Assumptions'!D26} -> 0.6 | E14: {='3. Key Assumptions'!E26} -> 0.75 | F14: {='3. Key Assumptions'!F26} -> 0.77 | G14: {='3. Key Assumptions'!G26} -> 0.78 | H14: {='3. Key Assumptions'!H26} -> 0.78 | I14: {='3. Key Assumptions'!I26} -> 0.78 | J14: {='3. Key Assumptions'!J26} -> 0.78 | ... L14: {='3. Key Assumptions'!L26} -> 0.78
B15: Occupied Room-Nights | C15: =C11*C14 -> 8030 | D15: =D11*D14 -> 12045 | E15: =E11*E14 -> 15056.25 | F15: =F11*F14 -> 15457.75 | G15: =G11*G14 -> 15658.5 | H15: =H11*H14 -> 15658.5 | I15: =I11*I14 -> 15658.5 | J15: =J11*J14 -> 15658.5 | ... L15: =L11*L14 -> 15658.5
B16: ADR (₹) | C16: 3800 | D16: 4200 | E16: 4500 | F16: 4800 | G16: 5000 | H16: 5250 | I16: 5513 | J16: 5788 | K16: 6078 | L16: 6381
B17: RevPAR (₹) | C17: =C14*C16 -> 1520 | D17: =D14*D16 -> 2520 | E17: =E14*E16 -> 3375 | F17: =F14*F16 -> 3696 | G17: =G14*G16 -> 3900 | H17: =H14*H16 -> 4095 | I17: =I14*I16 -> 4300.14 | J17: =J14*J16 -> 4514.64 | ... L17: =L14*L16 -> 4977.18
B19: REVENUE BREAKDOWN (₹ Crore)
B20: Room Revenue | C20: =C15*C16/10000000 -> 3.0514 | D20: =D15*D16/10000000 -> 5.0589 | E20: =E15*E16/10000000 -> 6.7753125 | F20: =F15*F16/10000000 -> 7.41972 | G20: =G15*G16/10000000 -> 7.82925 | H20: =H15*H16/10000000 -> 8.2207125 | I20: =I15*I16/10000000 -> 8.6325311 | J20: =J15*J16/10000000 -> 9.0631398 | ... L20: =L15*L16/10000000 -> 9.9916888
B21: F&B Revenue | C21: =C20/0.7*0.23 -> 1.0026029 | D21: =D20/0.7*0.23 -> 1.66221 | E21: =E20/0.7*0.23 -> 2.2261741 | F21: =F20/0.7*0.23 -> 2.437908 | G21: =G20/0.7*0.23 -> 2.5724679 | H21: =H20/0.7*0.23 -> 2.7010912 | I21: =I20/0.7*0.23 -> 2.8364031 | J21: =J20/0.7*0.23 -> 2.9778888 | ... L21: =L20/0.7*0.23 -> 3.2829835
B22: Other Revenue | C22: =C20/0.7*0.07 -> 0.30514 | D22: =D20/0.7*0.07 -> 0.50589 | E22: =E20/0.7*0.07 -> 0.67753125 | F22: =F20/0.7*0.07 -> 0.741972 | G22: =G20/0.7*0.07 -> 0.782925 | H22: =H20/0.7*0.07 -> 0.82207125 | I22: =I20/0.7*0.07 -> 0.86325311 | J22: =J20/0.7*0.07 -> 0.90631398 | ... L22: =L20/0.7*0.07 -> 0.99916889
B23: TOTAL REVENUE | C23: =SUM(C20:C22) -> 4.3591429 | D23: =SUM(D20:D22) -> 7.227 | E23: =SUM(E20:E22) -> 9.6790179 | F23: =SUM(F20:F22) -> 10.5996 | G23: =SUM(G20:G22) -> 11.184643 | H23: =SUM(H20:H22) -> 11.743875 | I23: =SUM(I20:I22) -> 12.332187 | J23: =SUM(J20:J22) -> 12.947343 | ... L23: =SUM(L20:L22) -> 14.273841
B25: SEGMENT BREAKDOWN (₹ Crore — Room Revenue Only)
B26: Medical Tourism (28%) | C26: =C20*0.28 -> 0.854392 | D26: =D20*0.28 -> 1.416492 | E26: =E20*0.28 -> 1.8970875 | F26: =F20*0.28 -> 2.0775216 | G26: =G20*0.28 -> 2.19219 | H26: =H20*0.28 -> 2.3017995 | I26: =I20*0.28 -> 2.4171087 | J26: =J20*0.28 -> 2.5376791 | ... L26: =L20*0.28 -> 2.7976729
B27: Corporate / Business (35%) | C27: =C20*0.35 -> 1.06799 | D27: =D20*0.35 -> 1.770615 | E27: =E20*0.35 -> 2.3713594 | F27: =F20*0.35 -> 2.596902 | G27: =G20*0.35 -> 2.7402375 | H27: =H20*0.35 -> 2.8772494 | I27: =I20*0.35 -> 3.0213859 | J27: =J20*0.35 -> 3.1720989 | ... L27: =L20*0.35 -> 3.4970911
B28: Leisure / Temple (22%) | C28: =C20*0.22 -> 0.671308 | D28: =D20*0.22 -> 1.112958 | E28: =E20*0.22 -> 1.4905687 | F28: =F20*0.22 -> 1.6323384 | G28: =G20*0.22 -> 1.722435 | H28: =H20*0.22 -> 1.8085567 | I28: =I20*0.22 -> 1.8991568 | J28: =J20*0.22 -> 1.9938908 | ... L28: =L20*0.22 -> 2.1981715
B29: MICE / Events (8%) | C29: =C20*0.08 -> 0.244112 | D29: =D20*0.08 -> 0.404712 | E29: =E20*0.08 -> 0.542025 | F29: =F20*0.08 -> 0.5935776 | G29: =G20*0.08 -> 0.62634 | H29: =H20*0.08 -> 0.657657 | I29: =I20*0.08 -> 0.69060248 | J29: =J20*0.08 -> 0.72505118 | ... L29: =L20*0.08 -> 0.79933511
B30: Airline Crews (7%) | C30: =C20*0.07 -> 0.213598 | D30: =D20*0.07 -> 0.354123 | E30: =E20*0.07 -> 0.47427188 | F30: =F20*0.07 -> 0.5193804 | G30: =G20*0.07 -> 0.5480475 | H30: =H20*0.07 -> 0.57544987 | I30: =I20*0.07 -> 0.60427717 | J30: =J20*0.07 -> 0.63441979 | ... L30: =L20*0.07 -> 0.69941822
B31: Total (Check = Room Revenue) | C31: =SUM(C26:C30) -> 3.0514 | D31: =SUM(D26:D30) -> 5.0589 | E31: =SUM(E26:E30) -> 6.7753125 | F31: =SUM(F26:F30) -> 7.41972 | G31: =SUM(G26:G30) -> 7.82925 | H31: =SUM(H26:H30) -> 8.2207125 | I31: =SUM(I26:I30) -> 8.6325311 | J31: =SUM(J26:J30) -> 9.0631398 | ... L31: =SUM(L26:L30) -> 9.9916888
B33: ANCHOR PARTNERSHIP OVERLAY
B34: MOU Realization % | C34: 0.6 | D34: 0.8 | E34: 1 | F34: 1 | G34: 1 | H34: 1 | I34: 1 | J34: 1 | K34: 1 | L34: 1
B35: Baseline Room-Nights/Month (at 100%) | C35: 180
B36: Realized Baseline (room-nights/yr) | C36: =$C$35*12*C34 -> 1296 | D36: =$C$35*12*D34 -> 1728 | E36: =$C$35*12*E34 -> 2160 | F36: =$C$35*12*F34 -> 2160 | G36: =$C$35*12*G34 -> 2160 | H36: =$C$35*12*H34 -> 2160 | I36: =$C$35*12*I34 -> 2160 | J36: =$C$35*12*J34 -> 2160 | ... L36: =$C$35*12*L34 -> 2160
B37: Baseline as % of Total Occupied | C37: =C36/C15 -> 0.16139477 | D37: =D36/D15 -> 0.14346202 | E37: =E36/E15 -> 0.14346202 | F37: =F36/F15 -> 0.13973573 | G37: =G36/G15 -> 0.13794425 | H37: =H36/H15 -> 0.13794425 | I37: =I36/I15 -> 0.13794425 | J37: =J36/J15 -> 0.13794425 | ... L37: =L36/L15 -> 0.13794425
B38: Baseline Occupancy Floor | C38: =C36/C11 -> 0.064557908 | D38: =D36/D11 -> 0.08607721 | E38: =E36/E11 -> 0.10759651 | F38: =F36/F11 -> 0.10759651 | G38: =G36/G11 -> 0.10759651 | H38: =H36/H11 -> 0.10759651 | I38: =I36/I11 -> 0.10759651 | J38: =J36/J11 -> 0.10759651 | ... L38: =L36/L11 -> 0.10759651
B40: YoY GROWTH METRICS
B41: Revenue Growth % | D41: =D23/C23-1 -> 0.65789474 | E41: =E23/D23-1 -> 0.33928571 | F41: =F23/E23-1 -> 0.095111111 | G41: =G23/F23-1 -> 0.055194805 | H41: =H23/G23-1 -> 0.05 | I41: =I23/H23-1 -> 0.050095238 | J41: =J23/I23-1 -> 0.049882097 | K41: =K23/J23-1 -> 0.050103663 | L41: =L23/K23-1 -> 0.049851925
B42: RevPAR Growth % | D42: =D17/C17-1 -> 0.65789474 | E42: =E17/D17-1 -> 0.33928571 | F42: =F17/E17-1 -> 0.095111111 | G42: =G17/F17-1 -> 0.055194805 | H42: =H17/G17-1 -> 0.05 | I42: =I17/H17-1 -> 0.050095238 | J42: =J17/I17-1 -> 0.049882097 | K42: =K17/J17-1 -> 0.050103663 | L42: =L17/K17-1 -> 0.049851925
B44: © 2025 Giritharan Chockalingam. All Rights Reserved. | This financial model and all associated intellectual property are proprietary and confidential.
B45: CONFIDENTIAL — For Board Approval Use Only | V3 Grand Madurai Investment Model v1.0 | Unauthorized reproduction or distribution is strictly prohibited.

Sheet 6. Revenue — Phased
B1: V3 GRAND MADURAI | Revenue — Phased | Base Case Analysis
B2: Prepared: February 2026 | Confidential - Board Use Only
B4: REVENUE MODEL — PHASED EXPANSION
B5: 55 → 72 Keys · 10-Year Projection · Base Case
C7: Year 1 | D7: Year 2 | E7: Year 3 | F7: Year 4 | G7: Year 5 | H7: Year 6 | I7: Year 7 | J7: Year 8 | K7: Year 9 | L7: Year 10
B8: PHASE 1 KEYS (55 rooms)
B9: Phase 1 Keys | C9: 55 | D9: 55 | E9: 55 | F9: 55 | G9: 55 | H9: 55 | I9: 55 | J9: 55 | K9: 55 | L9: 55
B10: Phase 1 Occupancy % | C10: {='3. Key Assumptions'!C26} -> 0.4 | D10: {='3. Key Assumptions'!D26} -> 0.6 | E10: {='3. Key Assumptions'!E26} -> 0.75 | F10: {='3. Key Assumptions'!F26} -> 0.77 | G10: {='3. Key Assumptions'!G26} -> 0.78 | H10: {='3. Key Assumptions'!H26} -> 0.78 | I10: {='3. Key Assumptions'!I26} -> 0.78 | J10: {='3. Key Assumptions'!J26} -> 0.78 | ... L10: {='3. Key Assumptions'!L26} -> 0.78
B11: Phase 1 Room-Nights | C11: =C9*365*C10 -> 8030 | D11: =D9*365*D10 -> 12045 | E11: =E9*365*E10 -> 15056.25 | F11: =F9*365*F10 -> 15457.75 | G11: =G9*365*G10 -> 15658.5 | H11: =H9*365*H10 -> 15658.5 | I11: =I9*365*I10 -> 15658.5 | J11: =J9*365*J10 -> 15658.5 | ... L11: =L9*365*L10 -> 15658.5
B12: Phase 1 ADR (₹) | C12: 3800 | D12: 4200 | E12: 4500 | F12: 4800 | G12: 5000 | H12: 5250 | I12: 5513 | J12: 5788 | K12: 6078 | L12: 6381
B13: Phase 1 Room Revenue (₹ Cr) | C13: =C11*C12/10000000 -> 3.0514 | D13: =D11*D12/10000000 -> 5.0589 | E13: =E11*E12/10000000 -> 6.7753125 | F13: =F11*F12/10000000 -> 7.41972 | G13: =G11*G12/10000000 -> 7.82925 | H13: =H11*H12/10000000 -> 8.2207125 | I13: =I11*I12/10000000 -> 8.6325311 | J13: =J11*J12/10000000 -> 9.0631398 | ... L13: =L11*L12/10000000 -> 9.9916888
B15: PHASE 2 KEYS (17 rooms — Opens Month 43)
B16: Phase 2 Keys | C16: 0 | D16: 0 | E16: 0 | F16: 17 | G16: 17 | H16: 17 | I16: 17 | J16: 17 | K16: 17 | L16: 17
B17: Months Operational (Year 4 partial) | C17: 0 | D17: 0 | E17: 0 | F17: 9 | G17: 12 | H17: 12 | I17: 12 | J17: 12 | K17: 12 | L17: 12
B18: Phase 2 Occupancy % | C18: 0 | D18: 0 | E18: 0 | F18: {='3. Key Assumptions'!F32} -> Recommended Hurdle Rates: | G18: {='3. Key Assumptions'!G32} -> 0 | H18: {='3. Key Assumptions'!H32} -> 0 | I18: {='3. Key Assumptions'!I32} -> 0 | J18: {='3. Key Assumptions'!J32} -> 0 | K18: {='3. Key Assumptions'!K32} -> 0 | L18: {='3. Key Assumptions'!L32} -> 0
B19: Phase 2 Available Room-Nights | C19: =C16*C17*30.4 -> 0 | D19: =D16*D17*30.4 -> 0 | E19: =E16*E17*30.4 -> 0 | F19: =F16*F17*30.4 -> 4651.2 | G19: =G16*G17*30.4 -> 6201.6 | H19: =H16*H17*30.4 -> 6201.6 | I19: =I16*I17*30.4 -> 6201.6 | J19: =J16*J17*30.4 -> 6201.6 | ... L19: =L16*L17*30.4 -> 6201.6
B20: Phase 2 Occupied Room-Nights | C20: =C19*C18 -> 0 | D20: =D19*D18 -> 0 | E20: =E19*E18 -> 0 | F20: =F19*F18 -> #VALUE! | G20: =G19*G18 -> 0 | H20: =H19*H18 -> 0 | I20: =I19*I18 -> 0 | J20: =J19*J18 -> 0 | ... L20: =L19*L18 -> 0
B21: Phase 2 ADR (₹) | C21: 0 | D21: 0 | E21: 0 | F21: 4800 | G21: 5000 | H21: 5250 | I21: 5513 | J21: 5788 | K21: 6078 | L21: 6381
B22: Phase 2 Room Revenue (₹ Cr) | C22: =C20*C21/10000000 -> 0 | D22: =D20*D21/10000000 -> 0 | E22: =E20*E21/10000000 -> 0 | F22: =F20*F21/10000000 -> #VALUE! | G22: =G20*G21/10000000 -> 0 | H22: =H20*H21/10000000 -> 0 | I22: =I20*I21/10000000 -> 0 | J22: =J20*J21/10000000 -> 0 | ... L22: =L20*L21/10000000 -> 0
B24: BLENDED TOTALS (55 + 17 KEYS)
B25: Total Keys Operational | C25: =C9+C16 -> 55 | D25: =D9+D16 -> 55 | E25: =E9+E16 -> 55 | F25: =F9+F16 -> 72 | G25: =G9+G16 -> 72 | H25: =H9+H16 -> 72 | I25: =I9+I16 -> 72 | J25: =J9+J16 -> 72 | ... L25: =L9+L16 -> 72
B26: Total Room Revenue (₹ Cr) | C26: =C13+C22 -> 3.0514 | D26: =D13+D22 -> 5.0589 | E26: =E13+E22 -> 6.7753125 | F26: =F13+F22 -> #VALUE! | G26: =G13+G22 -> 7.82925 | H26: =H13+H22 -> 8.2207125 | I26: =I13+I22 -> 8.6325311 | J26: =J13+J22 -> 9.0631398 | ... L26: =L13+L22 -> 9.9916888
B27: F&B Revenue (₹ Cr) | C27: =C26/0.7*0.23 -> 1.0026029 | D27: =D26/0.7*0.23 -> 1.66221 | E27: =E26/0.7*0.23 -> 2.2261741 | F27: =F26/0.7*0.23 -> #VALUE! | G27: =G26/0.7*0.23 -> 2.5724679 | H27: =H26/0.7*0.23 -> 2.7010912 | I27: =I26/0.7*0.23 -> 2.8364031 | J27: =J26/0.7*0.23 -> 2.9778888 | ... L27: =L26/0.7*0.23 -> 3.2829835
B28: Other Revenue (₹ Cr) | C28: =C26/0.7*0.07 -> 0.30514 | D28: =D26/0.7*0.07 -> 0.50589 | E28: =E26/0.7*0.07 -> 0.67753125 | F28: =F26/0.7*0.07 -> #VALUE! | G28: =G26/0.7*0.07 -> 0.782925 | H28: =H26/0.7*0.07 -> 0.82207125 | I28: =I26/0.7*0.07 -> 0.86325311 | J28: =J26/0.7*0.07 -> 0.90631398 | ... L28: =L26/0.7*0.07 -> 0.99916889
B29: TOTAL REVENUE (₹ Cr) | C29: =SUM(C26:C28) -> 4.3591429 | D29: =SUM(D26:D28) -> 7.227 | E29: =SUM(E26:E28) -> 9.6790179 | F29: =SUM(F26:F28) -> #VALUE! | G29: =SUM(G26:G28) -> 11.184643 | H29: =SUM(H26:H28) -> 11.743875 | I29: =SUM(I26:I28) -> 12.332187 | J29: =SUM(J26:J28) -> 12.947343 | ... L29: =SUM(L26:L28) -> 14.273841
B31: Blended Occupancy % | C31: =(C11+C20)/(C9*365+C19) -> 0.4 | D31: =(D11+D20)/(D9*365+D19) -> 0.6 | E31: =(E11+E20)/(E9*365+E19) -> 0.75 | F31: =(F11+F20)/(F9*365+F19) -> #VALUE! | G31: =(G11+G20)/(G9*365+G19) -> 0.59591043 | H31: =(H11+H20)/(H9*365+H19) -> 0.59591043 | I31: =(I11+I20)/(I9*365+I19) -> 0.59591043 | J31: =(J11+J20)/(J9*365+J19) -> 0.59591043 | ... L31: =(L11+L20)/(L9*365+L19) -> 0.59591043
B32: Blended RevPAR (₹) | C32: =C26*10000000/(C9*365+C19) -> 1520 | D32: =D26*10000000/(D9*365+D19) -> 2520 | E32: =E26*10000000/(E9*365+E19) -> 3375 | F32: =F26*10000000/(F9*365+F19) -> #VALUE! | G32: =G26*10000000/(G9*365+G19) -> 2979.5521 | H32: =H26*10000000/(H9*365+H19) -> 3128.5298 | I32: =I26*10000000/(I9*365+I19) -> 3285.2542 | J32: =J26*10000000/(J9*365+J19) -> 3449.1296 | ... L32: =L26*10000000/(L9*365+L19) -> 3802.5045
B34: INCREMENTAL PHASE 2 IMPACT
B35: Incremental Revenue (₹ Cr) | C35: =C22/0.7 -> 0 | D35: =D22/0.7 -> 0 | E35: =E22/0.7 -> 0 | F35: =F22/0.7 -> #VALUE! | G35: =G22/0.7 -> 0 | H35: =H22/0.7 -> 0 | I35: =I22/0.7 -> 0 | J35: =J22/0.7 -> 0 | ... L35: =L22/0.7 -> 0
B37: © 2025 Giritharan Chockalingam. All Rights Reserved. | This financial model and all associated intellectual property are proprietary and confidential.
B38: CONFIDENTIAL — For Board Approval Use Only | V3 Grand Madurai Investment Model v1.0 | Unauthorized reproduction or distribution is strictly prohibited.

Sheet 7. Operating Expenses
B1: Operating Expense Model
B2: V3 Grand Madurai • Confidential Board Material • February 2026
B4: OPERATING EXPENSE STRUCTURE
B5: Department-Level Detail · Fixed/Variable Split
C7: Year 1 | D7: Year 2 | E7: Year 3 | F7: Year 4 | G7: Year 5 | H7: Year 6 | I7: Year 7 | J7: Year 8 | K7: Year 9 | L7: Year 10
B8: Total Revenue (Phase 1 — 55 Keys) | C8: 7.33 | D8: 8.73 | E8: 10.02 | F8: 10.97 | G8: 11.59 | H8: 12.17 | I8: 12.77 | J8: 13.41 | K8: 14.08 | L8: 14.79
B10: OPERATING EXPENSES
B11: Rooms Department (18% of room rev) | C11: =C8*0.7*0.18 -> 0.92358 | D11: =D8*0.7*0.18 -> 1.09998 | E11: =E8*0.7*0.18 -> 1.26252 | F11: =F8*0.7*0.18 -> 1.38222 | G11: =G8*0.7*0.18 -> 1.46034 | H11: =H8*0.7*0.18 -> 1.53342 | I11: =I8*0.7*0.18 -> 1.60902 | J11: =J8*0.7*0.18 -> 1.68966 | ... L11: =L8*0.7*0.18 -> 1.86354
B12: F&B Cost of Goods (11% of revenue) | C12: =C8*0.11 -> 0.8063 | D12: =D8*0.11 -> 0.9603 | E12: =E8*0.11 -> 1.1022 | F12: =F8*0.11 -> 1.2067 | G12: =G8*0.11 -> 1.2749 | H12: =H8*0.11 -> 1.3387 | I12: =I8*0.11 -> 1.4047 | J12: =J8*0.11 -> 1.4751 | ... L12: =L8*0.11 -> 1.6269
B13: Sales & Marketing (5% of revenue) | C13: =C8*0.05 -> 0.3665 | D13: =D8*0.05 -> 0.4365 | E13: =E8*0.05 -> 0.501 | F13: =F8*0.05 -> 0.5485 | G13: =G8*0.05 -> 0.5795 | H13: =H8*0.05 -> 0.6085 | I13: =I8*0.05 -> 0.6385 | J13: =J8*0.05 -> 0.6705 | ... L13: =L8*0.05 -> 0.7395
B14: Utilities (5% of revenue) | C14: =C8*0.05 -> 0.3665 | D14: =D8*0.05 -> 0.4365 | E14: =E8*0.05 -> 0.501 | F14: =F8*0.05 -> 0.5485 | G14: =G8*0.05 -> 0.5795 | H14: =H8*0.05 -> 0.6085 | I14: =I8*0.05 -> 0.6385 | J14: =J8*0.05 -> 0.6705 | ... L14: =L8*0.05 -> 0.7395
B15: Repairs & Maintenance (3% of revenue) | C15: =C8*0.03 -> 0.2199 | D15: =D8*0.03 -> 0.2619 | E15: =E8*0.03 -> 0.3006 | F15: =F8*0.03 -> 0.3291 | G15: =G8*0.03 -> 0.3477 | H15: =H8*0.03 -> 0.3651 | I15: =I8*0.03 -> 0.3831 | J15: =J8*0.03 -> 0.4023 | ... L15: =L8*0.03 -> 0.4437
B16: Admin & General (8% of revenue) | C16: =C8*0.08 -> 0.5864 | D16: =D8*0.08 -> 0.6984 | E16: =E8*0.08 -> 0.8016 | F16: =F8*0.08 -> 0.8776 | G16: =G8*0.08 -> 0.9272 | H16: =H8*0.08 -> 0.9736 | I16: =I8*0.08 -> 1.0216 | J16: =J8*0.08 -> 1.0728 | ... L16: =L8*0.08 -> 1.1832
B17: Property Taxes (1.5% of revenue) | C17: =C8*0.015 -> 0.10995 | D17: =D8*0.015 -> 0.13095 | E17: =E8*0.015 -> 0.1503 | F17: =F8*0.015 -> 0.16455 | G17: =G8*0.015 -> 0.17385 | H17: =H8*0.015 -> 0.18255 | I17: =I8*0.015 -> 0.19155 | J17: =J8*0.015 -> 0.20115 | ... L17: =L8*0.015 -> 0.22185
B19: TOTAL OPERATING EXPENSES | C19: =SUM(C11:C17) -> 3.37913 | D19: =SUM(D11:D17) -> 4.02453 | E19: =SUM(E11:E17) -> 4.61922 | F19: =SUM(F11:F17) -> 5.05717 | G19: =SUM(G11:G17) -> 5.34299 | H19: =SUM(H11:H17) -> 5.61037 | I19: =SUM(I11:I17) -> 5.88697 | J19: =SUM(J11:J17) -> 6.18201 | ... L19: =SUM(L11:L17) -> 6.81819
B20: OpEx as % of Revenue | C20: =C19/C8 -> 0.461 | D20: =D19/D8 -> 0.461 | E20: =E19/E8 -> 0.461 | F20: =F19/F8 -> 0.461 | G20: =G19/G8 -> 0.461 | H20: =H19/H8 -> 0.461 | I20: =I19/I8 -> 0.461 | J20: =J19/J8 -> 0.461 | ... L20: =L19/L8 -> 0.461
B22: EBITDA (Phase 1) | C22: =C8-C19 -> 3.95087 | D22: =D8-D19 -> 4.70547 | E22: =E8-E19 -> 5.40078 | F22: =F8-F19 -> 5.91283 | G22: =G8-G19 -> 6.24701 | H22: =H8-H19 -> 6.55963 | I22: =I8-I19 -> 6.88303 | J22: =J8-J19 -> 7.22799 | ... L22: =L8-L19 -> 7.97181
B23: EBITDA Margin % | C23: =C22/C8 -> 0.539 | D23: =D22/D8 -> 0.539 | E23: =E22/E8 -> 0.539 | F23: =F22/F8 -> 0.539 | G23: =G22/G8 -> 0.539 | H23: =H22/H8 -> 0.539 | I23: =I22/I8 -> 0.539 | J23: =J22/J8 -> 0.539 | ... L23: =L22/L8 -> 0.539
B25: FIXED vs VARIABLE ANALYSIS
B26: Fixed Component (~40%) | C26: 2.6 | D26: 2.73 | E26: 2.87 | F26: 3.01 | G26: 3.16 | H26: 3.32 | I26: 3.48 | J26: 3.66 | K26: 3.84 | L26: 4.03
B27: Variable Component (~60%) | C27: =C19-C26 -> 0.77913 | D27: =D19-D26 -> 1.29453 | E27: =E19-E26 -> 1.74922 | F27: =F19-F26 -> 2.04717 | G27: =G19-G26 -> 2.18299 | H27: =H19-H26 -> 2.29037 | I27: =I19-I26 -> 2.40697 | J27: =J19-J26 -> 2.52201 | ... L27: =L19-L26 -> 2.78819
B28: Owner-Operator Savings (₹ Cr) | C28: 0.3 | D28: 0.3 | E28: 0.3 | F28: 0.3 | G28: 0.3 | H28: 0.3 | I28: 0.3 | J28: 0.3 | K28: 0.3 | L28: 0.3
B30: © 2025 Giritharan Chockalingam. All Rights Reserved. | This financial model and all associated intellectual property are proprietary and confidential.
B31: CONFIDENTIAL — For Board Approval Use Only | V3 Grand Madurai Investment Model v1.0 | Unauthorized reproduction or distribution is strictly prohibited.

Sheet 8. EBITDA & CF — P1
B1: EBITDA & Cash Flow — Phase 1
B2: V3 Grand Madurai • Confidential Board Material • February 2026
B4: EBITDA & CASH FLOW — PHASE 1
B5: P&L, Free Cash Flow & Debt Service · 55 Keys
B6: (₹ Crore) | C6: Year 1 | D6: Year 2 | E6: Year 3 | F6: Year 4 | G6: Year 5 | H6: Year 6 | I6: Year 7 | J6: Year 8 | K6: Year 9 | L6: Year 10
B7: Total Revenue | C7: 7.33 | D7: 8.73 | E7: 10.02 | F7: 10.97 | G7: 11.59 | H7: 12.17 | I7: 12.77 | J7: 13.41 | K7: 14.08 | L7: 14.79
B8: (-) Total Operating Expenses | C8: =C7*0.596 -> 4.36868 | D8: =D7*0.596 -> 5.20308 | E8: =E7*0.596 -> 5.97192 | F8: =F7*0.596 -> 6.53812 | G8: =G7*0.596 -> 6.90764 | H8: =H7*0.596 -> 7.25332 | I8: =I7*0.596 -> 7.61092 | J8: =J7*0.596 -> 7.99236 | ... L8: =L7*0.596 -> 8.81484
B10: EBITDA | C10: =C7-C8 -> 2.96132 | D10: =D7-D8 -> 3.52692 | E10: =E7-E8 -> 4.04808 | F10: =F7-F8 -> 4.43188 | G10: =G7-G8 -> 4.68236 | H10: =H7-H8 -> 4.91668 | I10: =I7-I8 -> 5.15908 | J10: =J7-J8 -> 5.41764 | ... L10: =L7-L8 -> 5.97516
B11: EBITDA Margin % | C11: =C10/C7 -> 0.404 | D11: =D10/D7 -> 0.404 | E11: =E10/E7 -> 0.404 | F11: =F10/F7 -> 0.404 | G11: =G10/G7 -> 0.404 | H11: =H10/H7 -> 0.404 | I11: =I10/I7 -> 0.404 | J11: =J10/J7 -> 0.404 | ... L11: =L10/L7 -> 0.404
B13: (-) Depreciation | C13: 1.04 | D13: 1.04 | E13: 1.04 | F13: 1.04 | G13: 1.04 | H13: 1.04 | I13: 1.04 | J13: 1.04 | K13: 1.04 | L13: 1.04
B14: EBIT | C14: =C10-C13 -> 1.92132 | D14: =D10-D13 -> 2.48692 | E14: =E10-E13 -> 3.00808 | F14: =F10-F13 -> 3.39188 | G14: =G10-G13 -> 3.64236 | H14: =H10-H13 -> 3.87668 | I14: =I10-I13 -> 4.11908 | J14: =J10-J13 -> 4.37764 | ... L14: =L10-L13 -> 4.93516
B15: (-) Interest Expense | C15: 1.43 | D15: 1.43 | E15: 1.43 | F15: 1.39 | G15: 1.34 | H15: 1.29 | I15: 1.24 | J15: 1.18 | K15: 1.11 | L15: 1.04
B16: Profit Before Tax (PBT) | C16: =C14-C15 -> 0.49132 | D16: =D14-D15 -> 1.05692 | E16: =E14-E15 -> 1.57808 | F16: =F14-F15 -> 2.00188 | G16: =G14-G15 -> 2.30236 | H16: =H14-H15 -> 2.58668 | I16: =I14-I15 -> 2.87908 | J16: =J14-J15 -> 3.19764 | ... L16: =L14-L15 -> 3.89516
B17: (-) Tax @ 25.17% | C17: =MAX(C16*0.2517,0) -> 0.12366524 | D17: =MAX(D16*0.2517,0) -> 0.26602676 | E17: =MAX(E16*0.2517,0) -> 0.39720274 | F17: =MAX(F16*0.2517,0) -> 0.5038732 | G17: =MAX(G16*0.2517,0) -> 0.57950401 | H17: =MAX(H16*0.2517,0) -> 0.65106736 | I17: =MAX(I16*0.2517,0) -> 0.72466444 | J17: =MAX(J16*0.2517,0) -> 0.80484599 | ... L17: =MAX(L16*0.2517,0) -> 0.98041177
B18: Profit After Tax (PAT) | C18: =C16-C17 -> 0.36765476 | D18: =D16-D17 -> 0.79089324 | E18: =E16-E17 -> 1.1808773 | F18: =F16-F17 -> 1.4980068 | G18: =G16-G17 -> 1.722856 | H18: =H16-H17 -> 1.9356126 | I18: =I16-I17 -> 2.1544156 | J18: =J16-J17 -> 2.392794 | ... L18: =L16-L17 -> 2.9147482
B20: FREE CASH FLOW
B21: PAT | C21: =C18 -> 0.36765476 | D21: =D18 -> 0.79089324 | E21: =E18 -> 1.1808773 | F21: =F18 -> 1.4980068 | G21: =G18 -> 1.722856 | H21: =H18 -> 1.9356126 | I21: =I18 -> 2.1544156 | J21: =J18 -> 2.392794 | ... L21: =L18 -> 2.9147482
B22: (+) Depreciation Add-back | C22: =C13 -> 1.04 | D22: =D13 -> 1.04 | E22: =E13 -> 1.04 | F22: =F13 -> 1.04 | G22: =G13 -> 1.04 | H22: =H13 -> 1.04 | I22: =I13 -> 1.04 | J22: =J13 -> 1.04 | ... L22: =L13 -> 1.04
B23: (-) Principal Repayment | C23: 0 | D23: 0 | E23: 0.41 | F23: 0.45 | G23: 0.5 | H23: 0.55 | I23: 0.6 | J23: 0.66 | K23: 0.73 | L23: 0.8
B24: (-) FF&E Reserve (3% from Yr 3) | C24: 0 | D24: 0 | E24: =E7*0.03 -> 0.3006 | F24: =F7*0.03 -> 0.3291 | G24: =G7*0.03 -> 0.3477 | H24: =H7*0.03 -> 0.3651 | I24: =I7*0.03 -> 0.3831 | J24: =J7*0.03 -> 0.4023 | K24: =K7*0.03 -> 0.4224 | L24: =L7*0.03 -> 0.4437
B25: (-) Working Capital Change | C25: =C8*30/365 -> 0.35906959 | D25: =D8*30/365 -> 0.42765041 | E25: =E8*30/365 -> 0.49084274 | F25: =F8*30/365 -> 0.53737973 | G25: =G8*30/365 -> 0.56775123 | H25: =H8*30/365 -> 0.59616329 | I25: =I8*30/365 -> 0.62555507 | J25: =J8*30/365 -> 0.6569063 | ... L25: =L8*30/365 -> 0.7245074
B27: FREE CASH FLOW TO EQUITY | C27: =C21+C22-C23-C24-C25 -> 1.0485852 | D27: =D21+D22-D23-D24-D25 -> 1.4032428 | E27: =E21+E22-E23-E24-E25 -> 1.0194345 | F27: =F21+F22-F23-F24-F25 -> 1.2215271 | G27: =G21+G22-G23-G24-G25 -> 1.3474048 | H27: =H21+H22-H23-H24-H25 -> 1.4643494 | I27: =I21+I22-I23-I24-I25 -> 1.5857605 | J27: =J21+J22-J23-J24-J25 -> 1.7135877 | ... L27: =L21+L22-L23-L24-L25 -> 1.9865408
B28: Cumulative FCF | C28: =C27-35.7 -> -34.651415 | D28: =C28+D27 -> -33.248172 | E28: =D28+E27 -> -32.228737 | F28: =E28+F27 -> -31.00721 | G28: =F28+G27 -> -29.659806 | H28: =G28+H27 -> -28.195456 | I28: =H28+I27 -> -26.609696 | J28: =I28+J27 -> -24.896108 | K28: =J28+K27 -> -23.05051 | L28: =K28+L27 -> -21.06397
B30: © 2025 Giritharan Chockalingam. All Rights Reserved. | This financial model and all associated intellectual property are proprietary and confidential.
B31: CONFIDENTIAL — For Board Approval Use Only | V3 Grand Madurai Investment Model v1.0 | Unauthorized reproduction or distribution is strictly prohibited.

Sheet 9. EBITDA & CF — Phased
B1: V3 GRAND MADURAI | EBITDA & CF — Phased | Base Case Analysis
B2: Prepared: February 2026 | Confidential - Board Use Only
B4: EBITDA & CASH FLOW — PHASED
B5: P&L, Free Cash Flow & Debt Service · 72 Keys
B6: (₹ Crore) | C6: Year 1 | D6: Year 2 | E6: Year 3 | F6: Year 4 | G6: Year 5 | H6: Year 6 | I6: Year 7 | J6: Year 8 | K6: Year 9 | L6: Year 10
B7: Total Revenue (Phased) | C7: 7.33 | D7: 8.73 | E7: 10.02 | F7: 12.64 | G7: 15.17 | H7: 15.93 | I7: 16.73 | J7: 17.57 | K7: 18.44 | L7: 19.37
B8: (-) Total Operating Expenses | C8: =C7*0.596 -> 4.36868 | D8: =D7*0.596 -> 5.20308 | E8: =E7*0.596 -> 5.97192 | F8: =F7*0.596 -> 7.53344 | G8: =G7*0.596 -> 9.04132 | H8: =H7*0.596 -> 9.49428 | I8: =I7*0.596 -> 9.97108 | J8: =J7*0.596 -> 10.47172 | ... L8: =L7*0.596 -> 11.54452
B10: EBITDA | C10: =C7-C8 -> 2.96132 | D10: =D7-D8 -> 3.52692 | E10: =E7-E8 -> 4.04808 | F10: =F7-F8 -> 5.10656 | G10: =G7-G8 -> 6.12868 | H10: =H7-H8 -> 6.43572 | I10: =I7-I8 -> 6.75892 | J10: =J7-J8 -> 7.09828 | ... L10: =L7-L8 -> 7.82548
B11: EBITDA Margin % | C11: =C10/C7 -> 0.404 | D11: =D10/D7 -> 0.404 | E11: =E10/E7 -> 0.404 | F11: =F10/F7 -> 0.404 | G11: =G10/G7 -> 0.404 | H11: =H10/H7 -> 0.404 | I11: =I10/I7 -> 0.404 | J11: =J10/J7 -> 0.404 | ... L11: =L10/L7 -> 0.404
B13: (-) Depreciation | C13: 1.04 | D13: 1.04 | E13: 1.04 | F13: 1.33 | G13: 1.33 | H13: 1.33 | I13: 1.33 | J13: 1.33 | K13: 1.33 | L13: 1.33
B14: EBIT | C14: =C10-C13 -> 1.92132 | D14: =D10-D13 -> 2.48692 | E14: =E10-E13 -> 3.00808 | F14: =F10-F13 -> 3.77656 | G14: =G10-G13 -> 4.79868 | H14: =H10-H13 -> 5.10572 | I14: =I10-I13 -> 5.42892 | J14: =J10-J13 -> 5.76828 | ... L14: =L10-L13 -> 6.49548
B15: (-) Interest Expense | C15: 1.43 | D15: 1.43 | E15: 1.43 | F15: 1.68 | G15: 1.63 | H15: 1.58 | I15: 1.52 | J15: 1.45 | K15: 1.37 | L15: 1.29
B16: Profit Before Tax (PBT) | C16: =C14-C15 -> 0.49132 | D16: =D14-D15 -> 1.05692 | E16: =E14-E15 -> 1.57808 | F16: =F14-F15 -> 2.09656 | G16: =G14-G15 -> 3.16868 | H16: =H14-H15 -> 3.52572 | I16: =I14-I15 -> 3.90892 | J16: =J14-J15 -> 4.31828 | ... L16: =L14-L15 -> 5.20548
B17: (-) Tax @ 25.17% | C17: =MAX(C16*0.2517,0) -> 0.12366524 | D17: =MAX(D16*0.2517,0) -> 0.26602676 | E17: =MAX(E16*0.2517,0) -> 0.39720274 | F17: =MAX(F16*0.2517,0) -> 0.52770415 | G17: =MAX(G16*0.2517,0) -> 0.79755676 | H17: =MAX(H16*0.2517,0) -> 0.88742372 | I17: =MAX(I16*0.2517,0) -> 0.98387516 | J17: =MAX(J16*0.2517,0) -> 1.0869111 | ... L17: =MAX(L16*0.2517,0) -> 1.3102193
B18: Profit After Tax (PAT) | C18: =C16-C17 -> 0.36765476 | D18: =D16-D17 -> 0.79089324 | E18: =E16-E17 -> 1.1808773 | F18: =F16-F17 -> 1.5688558 | G18: =G16-G17 -> 2.3711232 | H18: =H16-H17 -> 2.6382963 | I18: =I16-I17 -> 2.9250448 | J18: =J16-J17 -> 3.2313689 | ... L18: =L16-L17 -> 3.8952607
B20: FREE CASH FLOW
B21: PAT | C21: =C18 -> 0.36765476 | D21: =D18 -> 0.79089324 | E21: =E18 -> 1.1808773 | F21: =F18 -> 1.5688558 | G21: =G18 -> 2.3711232 | H21: =H18 -> 2.6382963 | I21: =I18 -> 2.9250448 | J21: =J18 -> 3.2313689 | ... L21: =L18 -> 3.8952607
B22: (+) Depreciation | C22: =C13 -> 1.04 | D22: =D13 -> 1.04 | E22: =E13 -> 1.04 | F22: =F13 -> 1.33 | G22: =G13 -> 1.33 | H22: =H13 -> 1.33 | I22: =I13 -> 1.33 | J22: =J13 -> 1.33 | ... L22: =L13 -> 1.33
B23: (-) Phase 2 CAPEX | C23: 0 | D23: 0 | E23: 0 | F23: 7.3 | G23: 0 | H23: 0 | I23: 0 | J23: 0 | K23: 0 | L23: 0
B24: (-) Principal Repayment | C24: 0 | D24: 0 | E24: 0.41 | F24: 0.45 | G24: 0.5 | H24: 0.63 | I24: 0.7 | J24: 0.77 | K24: 0.84 | L24: 0.93
B25: (-) FF&E Reserve (3% from Yr 3) | C25: 0 | D25: 0 | E25: =E7*0.03 -> 0.3006 | F25: =F7*0.03 -> 0.3792 | G25: =G7*0.03 -> 0.4551 | H25: =H7*0.03 -> 0.4779 | I25: =I7*0.03 -> 0.5019 | J25: =J7*0.03 -> 0.5271 | K25: =K7*0.03 -> 0.5532 | L25: =L7*0.03 -> 0.5811
B26: (-) Working Capital Change | C26: =C8*30/365 -> 0.35906959 | D26: =D8*30/365 -> 0.42765041 | E26: =E8*30/365 -> 0.49084274 | F26: =F8*30/365 -> 0.61918685 | G26: =G8*30/365 -> 0.74312219 | H26: =H8*30/365 -> 0.78035178 | I26: =I8*30/365 -> 0.81954082 | J26: =J8*30/365 -> 0.86068932 | ... L26: =L8*30/365 -> 0.94886466
B28: FREE CASH FLOW TO EQUITY | C28: =C21+C22-C23-C24-C25-C26 -> 1.0485852 | D28: =D21+D22-D23-D24-D25-D26 -> 1.4032428 | E28: =E21+E22-E23-E24-E25-E26 -> 1.0194345 | F28: =F21+F22-F23-F24-F25-F26 -> -5.849531 | G28: =G21+G22-G23-G24-G25-G26 -> 2.0029011 | H28: =H21+H22-H23-H24-H25-H26 -> 2.0800445 | I28: =I21+I22-I23-I24-I25-I26 -> 2.233604 | J28: =J21+J22-J23-J24-J25-J26 -> 2.4035796 | ... L28: =L21+L22-L23-L24-L25-L26 -> 2.765296
B29: Cumulative FCF (net of ₹43.0 Cr total) | C29: =C28-35.7 -> -34.651415 | D29: =C29+D28 -> -33.248172 | E29: =D29+E28 -> -32.228737 | F29: =E29+F28 -> -38.078268 | G29: =F29+G28 -> -36.075367 | H29: =G29+H28 -> -33.995323 | I29: =H29+I28 -> -31.761719 | J29: =I29+J28 -> -29.358139 | K29: =J29+K28 -> -26.770401 | L29: =K29+L28 -> -24.005105
B31: © 2025 Giritharan Chockalingam. All Rights Reserved. | This financial model and all associated intellectual property are proprietary and confidential.
B32: CONFIDENTIAL — For Board Approval Use Only | V3 Grand Madurai Investment Model v1.0 | Unauthorized reproduction or distribution is strictly prohibited.

Sheet 10. Returns Analysis
B2: RETURNS ANALYSIS
B3: IRR, NPV, Payback & Sensitivity · Phase 1 vs Phased
B5: PHASE 1 ONLY (55 KEYS) — ₹35.7 Cr Investment | O5: MULTI-VARIABLE SENSITIVITY ANALYSIS
C6: Year 0 | D6: Year 1 | E6: Year 2 | F6: Year 3 | G6: Year 4 | H6: Year 5 | I6: Year 6 | J6: Year 7 | K6: Year 8 | L6: Year 9 | M6: Year 10
B7: EBITDA | C7: 0 | D7: 2.93 | E7: 3.53 | F7: 4.05 | G7: 4.43 | H7: 4.48 | I7: 4.87 | J7: 5.3 | K7: 5.58 | L7: 5.84 | M7: 6.12 | O7: NPV Sensitivity to Key Variables (₹ Cr)
B8: (included in EBITDA — net of reserves) | C8: 0 | D8: 0 | E8: 0 | F8: 0 | G8: 0 | H8: 0 | I8: 0 | J8: 0 | K8: 0 | L8: 0 | M8: 0
B9: Exit Value (13.4x Year 10 EBITDA) | C9: 0 | D9: 0 | E9: 0 | F9: 0 | G9: 0 | H9: 0 | I9: 0 | J9: 0 | K9: 0 | L9: 0 | M9: 82.1 | O9: Occupancy ↓ / ADR → | P9: -10% | Q9: Base | R9: +10% | S9: +15%
B10: Net Cash Flow | C10: -35.7 | D10: =D7-D8+D9 -> 2.93 | E10: =E7-E8+E9 -> 3.53 | F10: =F7-F8+F9 -> 4.05 | G10: =G7-G8+G9 -> 4.43 | H10: =H7-H8+H9 -> 4.48 | I10: =I7-I8+I9 -> 4.87 | J10: =J7-J8+J9 -> 5.3 | K10: =K7-K8+K9 -> 5.58 | ... M10: =M7-M8+M9 -> 88.22 | O10: -10% | P10: -2.5 | Q10: 3.2 | R10: 9.8 | S10: 13.2
O11: -5% | P11: 2.1 | Q11: 7.5 | R11: 14.2 | S11: 18.5
B12: KEY METRICS | O12: Base (78%) | P12: 6.1 | Q12: 15.9 | R12: 22.4 | S12: 27.8
B13: 10-Year IRR | C13: =IRR(C10:M10) -> 0.17603612 | D13: ⚠️ MARGINAL (17.6% vs 17.5%) | O13: +5% | P13: 10.8 | Q13: 21.2 | R13: 28.5 | S13: 34.1
B14: NPV @ 17.5% | C14: =NPV(0.175,D10:M10)+C10 -> 0.22650427 | O14: +10% | P14: 15.2 | Q14: 26.8 | R14: 35.2 | S14: 41.8
B15: Return Multiple | C15: =SUM(D10:M10)/(-C10) -> 3.619888 | O15: +15% | P15: 19.5 | Q15: 32.1 | R15: 42.5 | S15: 50.2
B16: Payback Period (Years) | C16: 9.8 | D16: (Extended due to realistic occupancy)
B17: Exit Value | C17: =M9 -> 82.1
B18: Hurdle Rate | C18: 0.175 | D18: (Risk-Adjusted WACC)
B20: PHASED EXPANSION (55→72 KEYS) — ₹43.0 Cr Total Investment | O20: CAPEX ↓ / Margin → | P20: -2% | Q20: Base (40.4%) | R20: +2% | S20: +4%
C21: Year 0 | D21: Year 1 | E21: Year 2 | F21: Year 3 | G21: Year 4 | H21: Year 5 | I21: Year 6 | J21: Year 7 | K21: Year 8 | L21: Year 9 | M21: Year 10 | O21: +20% | P21: 0.112 | Q21: 0.135 | R21: 0.158 | S21: 0.181
B22: EBITDA | C22: 0 | D22: 2.93 | E22: 3.53 | F22: 4.05 | G22: 5.11 | H22: 6.07 | I22: 6.44 | J22: 6.88 | K22: 7.22 | L22: 7.68 | M22: 8.21 | O22: +10% | P22: 0.131 | Q22: 0.153 | R22: 0.176 | S22: 0.199
B23: (included in EBITDA — net of reserves) | C23: 0 | D23: 0 | E23: 0 | F23: 0 | G23: 0 | H23: 0 | I23: 0 | J23: 0 | K23: 0 | L23: 0 | M23: 0 | O23: Base (₹43 Cr) | P23: 0.148 | Q23: 0.178 | R23: 0.201 | S23: 0.225
B24: (-) Phase 2 CAPEX | C24: 0 | D24: 0 | E24: 0 | F24: 0 | G24: -7.3 | H24: 0 | I24: 0 | J24: 0 | K24: 0 | L24: 0 | M24: 0 | O24: -5% | P24: 0.162 | Q24: 0.192 | R24: 0.218 | S24: 0.242
B25: Exit Value (10.5x Year 10 EBITDA) | C25: 0 | D25: 0 | E25: 0 | F25: 0 | G25: 0 | H25: 0 | I25: 0 | J25: 0 | K25: 0 | L25: 0 | M25: 86.2 | O25: -10% | P25: 0.178 | Q25: 0.212 | R25: 0.238 | S25: 0.268
B26: Net Cash Flow | C26: -35.7 | D26: =D22-D23+D24+D25 -> 2.93 | E26: =E22-E23+E24+E25 -> 3.53 | F26: =F22-F23+F24+F25 -> 4.05 | G26: =G22-G23+G24+G25 -> -2.19 | H26: =H22-H23+H24+H25 -> 6.07 | I26: =I22-I23+I24+I25 -> 6.44 | J26: =J22-J23+J24+J25 -> 6.88 | K26: =K22-K23+K24+K25 -> 7.22 | ... M26: =M22-M23+M24+M25 -> 94.41
B28: KEY METRICS
B29: 10-Year IRR | C29: =IRR(C26:M26) -> 0.17797788 | D29: ⚠️ MARGINAL (17.8% vs 17.5%)
B30: NPV @ 17.5% | C30: =NPV(0.175,D26:M26)+C26 -> 0.68732818 | O30: Rev Growth ↓ / OpEx → | P30: +2% | Q30: Base | R30: -2% | S30: -4%
B31: Return Multiple | C31: =SUM(D26:M26)/(-C26) -> 3.8380952 | O31: -2% | P31: 9.8 | Q31: 8.9 | R31: 8.1 | S31: 7.5
B32: Payback Period (Years) | C32: 9.2 | D32: (~1.5 years longer than original estimate)
B33: Exit Value (12x EBITDA) | C33: =M25 -> 86.2 | O33: Base (5%) | P33: 8.6 | Q33: 7.8 | R33: 7.1 | S33: 6.5
O34: +2% | P34: 7.5 | Q34: 6.8 | R34: 6.2 | S34: 5.7
B35: TERMINAL VALUE — GORDON GROWTH MODEL | O35: +4% | P35: 6.5 | Q35: 5.9 | R35: 5.4 | S35: 5
B36: Year 10 EBITDA (Phased) | C36: 8.21
B37: Terminal Growth Rate | C37: 0.04
B38: WACC | C38: 0.175
B39: Terminal Value (Gordon Growth) | C39: =C36*(1+C37)/(C38-C37) -> 63.247407
B40: PV of Terminal Value | C40: =C39/(1+C38)^10 -> 12.608519 | O40: KEY ASSUMPTIONS (BASE CASE)
B41: Implied Exit Multiple | C41: =C39/C36 -> 7.7037037
O42: Assumption | P42: Value
B43: ⚠️ CRITICAL MODEL UPDATES - REALISTIC ASSUMPTIONS | O43: Total Investment | P43: ₹43.0 Cr
B44: Original Optimistic vs. Revised Reality-Based Model | C44: Stabilized ADR (₹) → | D44: 3500 | E44: 4000 | F44: 4500 | G44: 5000 | H44: 5500 | I44: 6000 | J44: 6500 | O44: Phase 1 Keys | P44: 55
...

Sheet 11. Scenario Stress Test
B1: V3 GRAND MADURAI | Scenario Stress Test | Base Case Analysis
B2: Prepared: February 2026 | Confidential - Board Use Only
B3: 📊 MODEL UPDATED: Feb 2026 - Now using 17.5% hurdle rate (proper WACC) vs. prior 12%
B4: Bear case occupancy updated to realistic ramp: 35-40% Y1, 50-55% Y2, 60-65% Y3+
B7: SCENARIO STRESS TEST
B8: Bear (20%) · Base (60%) · Bull (20%) · Probability-Weighted
B10: SCENARIO COMPARISON
C11: Bear Case | D11: Base Case | E11: Bull Case | F11: Expected
B12: Probability Weight | C12: 0.2 | D12: 0.6 | E12: 0.2
B14: KEY ASSUMPTIONS
B15: Stabilized Occupancy | C15: 35-40% Y1→60-65% Y3+ | D15: 75-78% | E15: 80-83%
B16: Stabilized ADR (₹) | C16: ₹4,500 | D16: ₹5,000 | E16: ₹6,000
B17: EBITDA Margin | C17: 0.36 | D17: 0.4 | E17: 0.42
B18: MOU Realization | C18: 60% of target | D18: 100% of target | E18: 120%+ of target
B19: Phase 2 Triggered? | C19: No (stays at 55 keys) | D19: Yes (72 keys) | E19: Yes (72 keys)
B20: Competitive Risk | C20: Residency Tower expands | D20: Status quo | E20: No new entrants
B22: RETURNS METRICS
B23: IRR (10-Year) | C23: 0.143 | D23: 0.178 | E23: 0.229 | F23: =C23*C12+D23*D12+E23*E12 -> 0.1812
B24: NPV @ 17.5% | C24: -2 | D24: 0.69 | E24: 18.5 | F24: 3.5
B25: Payback Period (Years) | C25: ⚠️ MARGINAL (9.5-10.0 yrs) | D25: ✅ PASS (9.2 yrs) | E25: 6.4 | F25: ✅ PASS (8.8 yrs)
B26: Return Multiple | C26: ❌ FAIL (1.95x < 2.0x) | D26: 2.71 | E26: 3.4 | F26: =C26*C12+D26*D12+E26*E12 -> #VALUE!
B27: Year 10 EBITDA (₹ Cr) | C27: 4.8 | D27: 7.83 | E27: 11.2 | F27: =C27*C12+D27*D12+E27*E12 -> 7.898
B28: Exit Value (₹ Cr) | C28: 57.6 | D28: 93.9 | E28: 134.4 | F28: =C28*C12+D28*D12+E28*E12 -> 94.74
B30: PROBABILITY-WEIGHTED EXPECTED IRR | C30: =F23 -> 0.1812 | D30: (vs. 12% hurdle rate)
B32: BEAR CASE SAFETY NET
B33: Even in bear case, IRR of 14.3% exceeds 12% hurdle rate
B34: IRR > 17.5% (Proper Hurdle) | C34: ❌ FAIL (14.3% < 17.5%) | D34: ⚠️ MARGINAL (17.8% vs 17.5%) | E34: ✅ PASS (22.9% >> 17.5%) | F34: ⚠️ MARGINAL (17.8% vs 17.5%)
B35: Anchor partnerships provide 8-11% occupancy floor
B36: Phase 2 NOT triggered in bear case — limits downside exposure
B37: Medical tourism provides counter-cyclical demand stability
B38: Owner-operator model saves ₹30L/year vs. external GM
B40: 10-YEAR REVENUE TRAJECTORY BY SCENARIO (₹ Crore)
C41: Year 1 | D41: Year 2 | E41: Year 3 | F41: Year 4 | G41: Year 5 | H41: Year 6 | I41: Year 7 | J41: Year 8 | K41: Year 9 | L41: Year 10
B42: Bear Case (55 keys) | C42: 5.5 | D42: 6.4 | E42: 7.2 | F42: 7.8 | G42: 8.2 | H42: 8.61 | I42: 9.04 | J42: 9.49 | K42: 9.97 | L42: 10.47
B43: Base Case (72 keys) | C43: 7.33 | D43: 8.73 | E43: 10.02 | F43: 12.64 | G43: 15.17 | H43: 15.93 | I43: 16.73 | J43: 17.57 | K43: 18.44 | L43: 19.37
B44: Bull Case (72 keys) | C44: 8.9 | D44: 10.8 | E44: 12.6 | F44: 16.4 | G44: 20.1 | H44: 21.3 | I44: 22.6 | J44: 23.95 | K44: 25.39 | L44: 26.91
B46: © 2025 Giritharan Chockalingam. All Rights Reserved. | This financial model and all associated intellectual property are proprietary and confidential.
B47: CONFIDENTIAL — For Board Approval Use Only | V3 Grand Madurai Investment Model v1.0 | Unauthorized reproduction or distribution is strictly prohibited.
B51: DECISION CRITERIA BY SCENARIO
B52: Criterion | C52: Bear | D52: Base | E52: Bull
...

Sheet 12. Operating Model Decision
B1: Operating Model Decision Framework
B2: V3 Grand Madurai • Confidential Board Material • February 2026
B4: OPERATING MODEL DECISION | P4: CF Helpers (hidden)
B5: Independent vs IHG vs IHCL Taj vs Marriott vs Lemon Tree | P5: -43 | Q5: =C31 -> 2.96132 | R5: =D31 -> 3.52692 | S5: =E31 -> 4.04808 | T5: =F31 -> 5.10656 | U5: =G31-7.3 -> -1.17132 | V5: =H31 -> 6.43572 | W5: =I31 -> 6.75892 | X5: =J31 -> 7.09828 | Y5: =K31 -> 7.44976 | Z5: =L31+L31*12 -> 101.73124
P6: -43.9 | Q6: =C37 -> 2.5614443 | R6: =D37 -> 3.0678593 | S6: =E37 -> 3.5344845 | T6: =F37 -> 4.482204 | U6: =G37-7.3 -> -1.9026317 | V6: =H37 -> 5.6722793 | W6: =I37 -> 5.9616593 | X6: =J37 -> 6.2655083 | Y6: =K37 -> 6.580209 | Z6: =L37+L37*12 -> 89.915972
P7: -45 | Q7: =C47 -> 1.9882418 | R7: =D47 -> 2.4634858 | S7: =E47 -> 2.9013892 | T7: =F47 -> 3.7907744 | U7: =G47-7.3 -> -2.6503918 | V7: =H47 -> 4.9075978 | W7: =I47 -> 5.1791658 | X7: =J47 -> 5.4643122 | Y7: =K47 -> 5.7596424 | Z7: =L47+L47*12 -> 78.979423
B8: OPERATING MODEL COMPARISON | P8: -45.75 | Q8: =C56 -> 1.6780074 | R8: =D56 -> 2.1083226 | S8: =E56 -> 2.5048274 | T8: =F56 -> 3.3101315 | U8: =G56-7.3 -> -3.2122274 | V8: =H56 -> 4.3213722 | W8: =I56 -> 4.5672666 | X8: =J56 -> 4.8254558 | Y8: =K56 -> 5.0928659 | Z8: =L56+L56*12 -> 69.923336
B9: Dimension | C9: 1. Independent Owner-Operated (Selected ✓) | D9: 2. IHG / Wyndham Franchise | E9: 3. IHCL (Taj) / ITC Mgmt Contract | F9: 4. Marriott / Hyatt Mgmt Contract | G9: 5. Lemon Tree / Keys Select (Franchise-Lite) | P9: -43.45 | Q9: =C63 -> 2.323323 | R9: =D63 -> 2.775663 | S9: =E63 -> 3.192462 | T9: =F63 -> 4.038984 | U9: =G63-7.3 -> -2.443573 | V9: =H63 -> 5.101983 | W9: =I63 -> 5.360463 | X9: =J63 -> 5.631867 | Y9: =K63 -> 5.912964 | Z9: =L63+L63*12 -> 80.774811
B10: Minimum Key Requirement | C10: No minimum — any size | D10: IHG Holiday Inn Express: 75+ keys; Wyndham Ramada: 50+ keys — 72 keys QUALIFIES | E10: Taj/Vivanta: 100+ keys; Ginger (IHCL budget): 80+ keys — 72 keys DOES NOT QUALIFY for Taj; marginal for Ginger | F10: Marriott Courtyard/Fairfield: 100+ keys; Hyatt Place: 100+ keys — 72 keys DOES NOT QUALIFY | G10: Lemon Tree: 50+ keys; Keys Select: 40+ keys — 72 keys QUALIFIES easily
B11: Fee Structure | C11: ₹0 — Zero recurring fees to any brand or operator | D11: IHG: 5% royalty + 2.5% marketing + 1% reservation = 8.5% of gross room revenue; Wyndham: 4.5% royalty + 2% marketing = 6.5% | E11: IHCL base fee: 2.5% of total revenue + incentive fee: 8-10% of GOP (Gross Operating Profit) + technical services: 1-2% of revenue + marketing: 2% | F11: Marriott base: 3% of total revenue + incentive: 8-10% of GOP + system/loyalty: 5.5% of room revenue + marketing: 1.5% of revenue | G11: Lemon Tree: 3% of revenue + 1.5% marketing = 4.5% total; Keys Select: similar structure
B12: Total Fee Burden (@ ₹15 Cr stabilized revenue) | C12: ₹0 per year | D12: ₹0.98 - 1.28 Cr/year (6.5-8.5% of room revenue ≈ 70% of ₹15 Cr) | E12: ₹1.47 - 1.98 Cr/year (base 2.5% + incentive 8% of 40% GOP + tech/mktg 3%) | F12: ₹1.80 - 2.25 Cr/year (base 3% + incentive 10% of GOP + system 5.5% room rev + mktg) | G12: ₹0.68 Cr/year (4.5% of total revenue)
